<mujoco model="spirob">
    <compiler angle="radian" meshdir="C:\Users\secre\Documents\GitHub\TwoString\twoStringSTL"/>

    <asset>
        <mesh file="TwoString1.STL" />
        <mesh file="TwoString2.STL" />
        <mesh file="TwoString3.STL" />
    </asset>

    <worldbody>
        <light directional="true" pos="-0.5 0.5 3" dir="0 0 -1" />
        <geom name="floor" pos="0 0 0" size="1 1 1" type="plane" rgba="1 0.83 0.61 0.5"/>

        <body name="base" pos="0 0 0.1">
            <geom name="segment1" type="mesh" mesh="TwoString1" pos="0 0 0" contype="1" conaffinity="1"/>
            <inertial pos="0 0 0" mass="1" diaginertia="0.1 0.1 0.1"/>
            <site name="cable_anchor1" pos="0 0.215724 0.004246" size="0.01" rgba="1 0 0 1"/>
            <site name="cable2_anchor1" pos="0 -0.215724 0.004246" size="0.01" rgba="1 0 0 1"/>

            <body name="segment2" pos="0 0 0">
                <joint name="joint2" type="ball" pos="0 0 0" stiffness="50" damping="5"/>
                <geom name="segment2" type="mesh" mesh="TwoString2" pos="0 0 0" contype="1" conaffinity="1"/>
                <inertial pos="0 0 0" mass="1" diaginertia="0.1 0.1 0.1"/>
                <site name="cable_anchor2" pos="0 0.196938 0.246226" size="0.01" rgba="1 0 0 1"/>
                <site name="cable2_anchor2" pos="0 -0.196938 0.246226" size="0.01" rgba="1 0 0 1"/>

                <body name="segment3" pos="0 0 0">
                    <joint name="joint3" type="ball" pos="0 0 0" stiffness="50" damping="5"/>
                    <geom name="segment3" type="mesh" mesh="TwoString3" pos="0 0 0" contype="1" conaffinity="1"/>
                    <inertial pos="0 0 0" mass="1" diaginertia="0.1 0.1 0.1"/>
                    <site name="cable_anchor3" pos="0 0.177578 0.489842" size="0.01" rgba="1 0 0 1"/>
                    <site name="cable2_anchor3" pos="0 -0.177578 0.489842" size="0.01" rgba="1 0 0 1"/>
                </body>
            </body>
        </body>
    </worldbody>

    <tendon>
        <spatial name="cable1" stiffness="250" damping="10">
            <site site="cable_anchor1" />
            <site site="cable_anchor2" />
            <site site="cable_anchor3" />
        </spatial>
        <spatial name="cable2" stiffness="250" damping="10">
            <site site="cable2_anchor1" />
            <site site="cable2_anchor2" />
            <site site="cable2_anchor3" />
        </spatial>
    </tendon>

    <contact>
        <pair geom1="segment2" geom2="segment3"/>
    </contact>

    <actuator>
        <motor name="cable_motor" tendon="cable1" gear="100"/>
        <motor name="cable_motor2" tendon="cable2" gear="100"/>
    </actuator>
</mujoco>
