<mujoco model="spirob">
    <compiler angle="radian" meshdir="C:\Users\secre\Documents\GitHub\TwoString\twoStringSTL"/>

    <asset>
        <mesh file="TwoString1.STL" />
        <mesh file="TwoString2.STL" />
        <mesh file="TwoString3.STL" />
        <mesh file="TwoString4.STL" />
        <mesh file="TwoString5.STL" />
        <mesh file="TwoString6.STL" />
        <mesh file="TwoString7.STL" />
        <mesh file="TwoString8.STL" />
        <mesh file="TwoString9.STL" />
        <mesh file="TwoString10.STL" />
        <mesh file="TwoString11.STL" />
        <mesh file="TwoString12.STL" />
        <mesh file="TwoString13.STL" />
        <mesh file="TwoString14.STL" />
        <mesh file="TwoString15.STL" />
        <mesh file="TwoString16.STL" />
        <mesh file="TwoString17.STL" />
        <mesh file="TwoString18.STL" />
        <mesh file="TwoString19.STL" />
    </asset>

    <worldbody>
        <light directional="true" pos="-0.5 0.5 3" dir="0 0 -1" />
        <geom name="floor" pos="0 0 -10" size="1 1 1" type="plane" rgba="1 0.83 0.61 0.5"/>

        <body name="base" pos="0 0 0.1">
            <geom name="segment1" type="mesh" mesh="TwoString1" pos="0 0 0" contype="1" conaffinity="1"/>
            <inertial pos="0 0 0" mass="0.01" diaginertia="0.1 0.1 0.1"/>
            <site name="cable_anchor1" pos="0 0.215724 0.004246" size="0.01" rgba="1 0 0 1"/>
            <site name="cable2_anchor1" pos="0 -0.215724 0.004246" size="0.01" rgba="1 0 0 1"/>

            <body name="segment2" pos="0 0 0">
                <joint name="joint2" type="ball" pos="0 0 0.087206" stiffness="5" damping="5"/>
                <geom name="segment2" type="mesh" mesh="TwoString2" pos="0 0 0" contype="1" conaffinity="1"/>
                <inertial pos="0 0 0" mass="0.01" diaginertia="0.1 0.1 0.1"/>
                <site name="cable_anchor2" pos="0 0.196938 0.246226" size="0.01" rgba="1 0 0 1"/>
                <site name="cable2_anchor2" pos="0 -0.196938 0.246226" size="0.01" rgba="1 0 0 1"/>

                <body name="segment3" pos="0 0 0">
                    <joint name="joint3" type="ball" pos="0 0 0.341718" stiffness="5" damping="5"/>
                    <geom name="segment3" type="mesh" mesh="TwoString3" pos="0 0 0" contype="1" conaffinity="1"/>
                    <inertial pos="0 0 0" mass="0.01" diaginertia="0.1 0.1 0.1"/>
                    <site name="cable_anchor3" pos="0 0.177578 0.489842" size="0.01" rgba="1 0 0 1"/>
                    <site name="cable2_anchor3" pos="0 -0.177578 0.489842" size="0.01" rgba="1 0 0 1"/>
                    
                    <body name="segment4" pos="0 0 0">
                        <joint name="joint4" type="ball" pos="0 0 0.573951" stiffness="5" damping="5"/>
                        <geom name="segment4" type="mesh" mesh="TwoString4" pos="0 0 0" contype="1" conaffinity="1"/>
                        <inertial pos="0 0 0" mass="0.01" diaginertia="0.1 0.1 0.1"/>
                        <site name="cable_anchor4" pos="0 0.161404 0.708246" size="0.01" rgba="1 0 0 1"/>
                        <site name="cable2_anchor4" pos="0 -0.161404 0.708246" size="0.01" rgba="1 0 0 1"/>

                        <body name="segment5" pos="0 0 0">
                            <joint name="joint5" type="ball" pos="0 0 0.785344" stiffness="5" damping="5"/>
                            <geom name="segment5" type="mesh" mesh="TwoString5" pos="0 0 0" contype="1" conaffinity="1"/>
                            <inertial pos="0 0 0" mass="0.01" diaginertia="0.1 0.1 0.1"/>
                            <site name="cable_anchor5" pos="0 0.146931 0.90759" size="0.01" rgba="1 0 0 1"/>
                            <site name="cable2_anchor5" pos="0 -0.146931 0.90759" size="0.01" rgba="1 0 0 1"/>

                            <body name="segment6" pos="0 0 0">
                                <joint name="joint6" type="ball" pos="0 0 0.979154" stiffness="5" damping="5"/>
                                <geom name="segment6" type="mesh" mesh="TwoString6" pos="0 0 0" contype="1" conaffinity="1"/>
                                <inertial pos="0 0 0" mass="0.01" diaginertia="0.1 0.1 0.1"/>
                                <site name="cable_anchor6" pos="0 0.130886 1.08744" size="0.01" rgba="1 0 0 1"/>
                                <site name="cable2_anchor6" pos="0 -0.130886 1.08744" size="0.01" rgba="1 0 0 1"/>

                                <body name="segment7" pos="0 0 0">
                                    <joint name="joint7" type="ball" pos="0 0 1.15587" stiffness="5" damping="5"/>
                                    <geom name="segment7" type="mesh" mesh="TwoString7" pos="0 0 0" contype="1" conaffinity="1"/>
                                    <inertial pos="0 0 0" mass="0.01" diaginertia="0.1 0.1 0.1"/>
                                    <site name="cable_anchor7" pos="0 0.118223 1.25331" size="0.01" rgba="1 0 0 1"/>
                                    <site name="cable2_anchor7" pos="0 -0.118223 1.25331" size="0.01" rgba="1 0 0 1"/>

                                    <body name="segment8" pos="0 0 0">
                                        <joint name="joint8" type="ball" pos="0 0 1.31703" stiffness="5" damping="5"/>
                                        <geom name="segment8" type="mesh" mesh="TwoString8" pos="0 0 0" contype="1" conaffinity="1"/>
                                        <inertial pos="0 0 0" mass="0.01" diaginertia="0.1 0.1 0.1"/>
                                        <site name="cable_anchor8" pos="0 0.106827 1.40347" size="0.01" rgba="1 0 0 1"/>
                                        <site name="cable2_anchor8" pos="0 -0.106827 1.40347" size="0.01" rgba="1 0 0 1"/>

                                        <body name="segment9" pos="0 0 0">
                                            <joint name="joint9" type="ball" pos="0 0 1.46327" stiffness="5" damping="5"/>
                                            <geom name="segment9" type="mesh" mesh="TwoString9" pos="0 0 0" contype="1" conaffinity="1"/>
                                            <inertial pos="0 0 0" mass="0.01" diaginertia="0.1 0.1 0.1"/>
                                            <site name="cable_anchor9" pos="0 0.095196 1.54547" size="0.01" rgba="1 0 0 1"/>
                                            <site name="cable2_anchor9" pos="0 -0.095196 1.54547" size="0.01" rgba="1 0 0 1"/>

                                            <body name="segment10" pos="0 0 0">
                                                <joint name="joint10" type="ball" pos="0 0 1.5971" stiffness="5" damping="5"/>
                                                <geom name="segment10" type="mesh" mesh="TwoString10" pos="0 0 0" contype="1" conaffinity="1"/>
                                                <inertial pos="0 0 0" mass="0.01" diaginertia="0.1 0.1 0.1"/>
                                                <site name="cable_anchor10" pos="0 0.085396 1.6723" size="0.01" rgba="1 0 0 1"/>
                                                <site name="cable2_anchor10" pos="0 -0.085396 1.6723" size="0.01" rgba="1 0 0 1"/>

                                                <body name="segment11" pos="0 0 0">
                                                    <joint name="joint11" type="ball" pos="0 0 1.71956" stiffness="5" damping="5"/>
                                                    <geom name="segment11" type="mesh" mesh="TwoString11" pos="0 0 0" contype="1" conaffinity="1"/>
                                                    <inertial pos="0 0 0" mass="0.01" diaginertia="0.1 0.1 0.1"/>
                                                    <site name="cable_anchor11" pos="0 0.077382 1.78859" size="0.01" rgba="1 0 0 1"/>
                                                    <site name="cable2_anchor11" pos="0 0.077382 1.78859" size="0.01" rgba="1 0 0 1"/>

                                                    <body name="segment12" pos="0 0 0">
                                                        <joint name="joint12" type="ball" pos="0 0 1.83147" stiffness="5" damping="5"/>
                                                        <geom name="segment12" type="mesh" mesh="TwoString12" pos="0 0 0" contype="1" conaffinity="1"/>
                                                        <inertial pos="0 0 0" mass="0.01" diaginertia="0.1 0.1 0.1"/>
                                                        <site name="cable_anchor12" pos="0 0.068901 1.89233" size="0.01" rgba="1 0 0 1"/>
                                                        <site name="cable2_anchor12" pos="0 -0.068901 1.89233" size="0.01" rgba="1 0 0 1"/>

                                                        <body name="segment13" pos="0 0 0">
                                                            <joint name="joint13" type="ball" pos="0 0 1.93331" stiffness="5" damping="5"/>
                                                            <geom name="segment13" type="mesh" mesh="TwoString13" pos="0 0 0" contype="1" conaffinity="1"/>
                                                            <inertial pos="0 0 0" mass="0.01" diaginertia="0.1 0.1 0.1"/>
                                                            <site name="cable_anchor13" pos="0 0.061429 1.98839" size="0.01" rgba="1 0 0 1"/>
                                                            <site name="cable2_anchor13" pos="0 0.061429 1.98839" size="0.01" rgba="1 0 0 1"/>

                                                            <body name="segment14" pos="0 0 0">
                                                                <joint name="joint14" type="ball" pos="0 0 2.02623" stiffness="5" damping="5"/>
                                                                <geom name="segment14" type="mesh" mesh="TwoString14" pos="0 0 0" contype="1" conaffinity="1"/>
                                                                <inertial pos="0 0 0" mass="0.01" diaginertia="0.1 0.1 0.1"/>
                                                                <site name="cable_anchor14" pos="0 0.053719 2.0779" size="0.01" rgba="1 0 0 1"/>
                                                                <site name="cable2_anchor14" pos="0 0.053719 2.0779" size="0.01" rgba="1 0 0 1"/>

                                                                <body name="segment15" pos="0 0 0">
                                                                    <joint name="joint15" type="ball" pos="0 0 2.11129" stiffness="5" damping="5"/>
                                                                    <geom name="segment15" type="mesh" mesh="TwoString15" pos="0 0 0" contype="1" conaffinity="1"/>
                                                                    <inertial pos="0 0 0" mass="0.01" diaginertia="0.1 0.1 0.1"/>
                                                                    <site name="cable_anchor15" pos="0 0.047341 2.15696" size="0.01" rgba="1 0 0 1"/>
                                                                    <site name="cable2_anchor15" pos="0 -0.047341 2.15696" size="0.01" rgba="1 0 0 1"/>

                                                                    <body name="segment16" pos="0 0 0">
                                                                        <joint name="joint16" type="ball" pos="0 0 2.18878" stiffness="5" damping="5"/>
                                                                        <geom name="segment16" type="mesh" mesh="TwoString16" pos="0 0 0" contype="1" conaffinity="1"/>
                                                                        <inertial pos="0 0 0" mass="0.01" diaginertia="0.1 0.1 0.1"/>
                                                                        <site name="cable_anchor16" pos="0 0.041663 2.22831" size="0.01" rgba="1 0 0 1"/>
                                                                        <site name="cable2_anchor16" pos="0 -0.041663 2.22831" size="0.01" rgba="1 0 0 1"/>

                                                                        <body name="segment17" pos="0 0 0">
                                                                            <joint name="joint17" type="ball" pos="0 0 2.25939" stiffness="5" damping="5"/>
                                                                            <geom name="segment17" type="mesh" mesh="TwoString17" pos="0 0 0" contype="1" conaffinity="1"/>
                                                                            <inertial pos="0 0 0" mass="0.01" diaginertia="0.1 0.1 0.1"/>
                                                                            <site name="cable_anchor17" pos="0 0.036056 2.29833" size="0.01" rgba="1 0 0 1"/>
                                                                            <site name="cable2_anchor17" pos="0 -0.036056 2.29833" size="0.01" rgba="1 0 0 1"/>

                                                                            <body name="segment18" pos="0 0 0">
                                                                                <joint name="joint18" type="ball" pos="0 0 2.32365" stiffness="5" damping="5"/>
                                                                                <geom name="segment18" type="mesh" mesh="TwoString18" pos="0 0 0" contype="1" conaffinity="1"/>
                                                                                <inertial pos="0 0 0" mass="0.01" diaginertia="0.1 0.1 0.1"/>
                                                                                <site name="cable_anchor18" pos="0 0.030869 2.35889" size="0.01" rgba="1 0 0 1"/>
                                                                                <site name="cable2_anchor18" pos="0 -0.030869 2.35889" size="0.01" rgba="1 0 0 1"/>

                                                                                <body name="segment19" pos="0 0 0">
                                                                                    <joint name="joint19" type="ball" pos="0 0 2.38202" stiffness="5" damping="5"/>
                                                                                    <geom name="segment19" type="mesh" mesh="TwoString19" pos="0 0 0" contype="1" conaffinity="1"/>
                                                                                    <inertial pos="0 0 0" mass="0.01" diaginertia="0.1 0.1 0.1"/>
                                                                                    <site name="cable_anchor19" pos="0 0.026804 2.41412" size="0.01" rgba="1 0 0 1"/>
                                                                                    <site name="cable2_anchor19" pos="0 -0.026804 2.41412" size="0.01" rgba="1 0 0 1"/>
                                                                                </body>
                                                                            </body>
                                                                        </body>
                                                                    </body>
                                                                </body>
                                                            </body>
                                                        </body>
                                                    </body>
                                                </body>
                                            </body>
                                        </body>
                                    </body>
                                </body>
                            </body>
                        </body>
                    </body>
                </body>
            </body>
        </body>
    </worldbody>
    <tendon>
        <spatial name="cable1" stiffness="40" damping="10">
            <site site="cable_anchor1" />
            <site site="cable_anchor2" />
            <site site="cable_anchor3" />
            <site site="cable_anchor4" />
            <site site="cable_anchor5" />
            <site site="cable_anchor6" />
            <site site="cable_anchor7" />
            <site site="cable_anchor8" />
            <site site="cable_anchor9" />
            <site site="cable_anchor10" />
            <site site="cable_anchor11" />
            <site site="cable_anchor12" />
            <site site="cable_anchor13" />
            <site site="cable_anchor14" />
            <site site="cable_anchor15" />
            <site site="cable_anchor16" />
            <site site="cable_anchor17" />
            <site site="cable_anchor18" />
            <site site="cable_anchor19" />
        </spatial>

        <spatial name="cable2" stiffness="40" damping="10">
            <site site="cable2_anchor1" />
            <site site="cable2_anchor2" />
            <site site="cable2_anchor3" />
            <site site="cable2_anchor4" />
            <site site="cable2_anchor5" />
            <site site="cable2_anchor6" />
            <site site="cable2_anchor7" />
            <site site="cable2_anchor8" />
            <site site="cable2_anchor9" />
            <site site="cable2_anchor10" />
            <site site="cable2_anchor11" />
            <site site="cable2_anchor12" />
            <site site="cable2_anchor13" />
            <site site="cable2_anchor14" />
            <site site="cable2_anchor15" />
            <site site="cable2_anchor16" />
            <site site="cable2_anchor17" />
            <site site="cable2_anchor18" />
            <site site="cable2_anchor19" />
        </spatial>
    </tendon>

    <contact>
        <pair geom1="segment2" geom2="segment3"/>
        <pair geom1="segment3" geom2="segment4"/>
        <pair geom1="segment4" geom2="segment5"/>
        <pair geom1="segment5" geom2="segment6"/>
        <pair geom1="segment6" geom2="segment7"/>
        <pair geom1="segment7" geom2="segment8"/>
        <pair geom1="segment8" geom2="segment9"/>
        <pair geom1="segment9" geom2="segment10"/>
        <pair geom1="segment10" geom2="segment11"/>
        <pair geom1="segment11" geom2="segment12"/>
        <pair geom1="segment12" geom2="segment13"/>
        <pair geom1="segment13" geom2="segment14"/>
        <pair geom1="segment14" geom2="segment15"/>
        <pair geom1="segment15" geom2="segment16"/>
        <pair geom1="segment16" geom2="segment17"/>
        <pair geom1="segment17" geom2="segment18"/>
        <pair geom1="segment18" geom2="segment19"/>
    </contact>

    <actuator>
        <motor name="cable_motor" tendon="cable1" gear="50"/>
        <motor name="cable_motor2" tendon="cable2" gear="50"/>
    </actuator>
</mujoco>
